<?xml version="1.0" encoding="utf-8"?><testsuites><testsuite name="pytest" errors="1" failures="0" skipped="0" tests="1" time="94.165" timestamp="2021-01-20T14:33:29.058080" hostname="DESKTOP-9CB8V9A"><testcase time="7.701" /><testcase classname="pytest" name="internal" time="0.000"><error message="internal error">Traceback (most recent call last):
  File "c:\users\ssrk1\appdata\local\programs\python\python38-32\lib\site-packages\_pytest\main.py", line 257, in wrap_session
    session.exitstatus = doit(config, session) or 0
  File "c:\users\ssrk1\appdata\local\programs\python\python38-32\lib\site-packages\_pytest\main.py", line 313, in _main
    config.hook.pytest_runtestloop(session=session)
  File "c:\users\ssrk1\appdata\local\programs\python\python38-32\lib\site-packages\pluggy\hooks.py", line 286, in __call__
    return self._hookexec(self, self.get_hookimpls(), kwargs)
  File "c:\users\ssrk1\appdata\local\programs\python\python38-32\lib\site-packages\pluggy\manager.py", line 93, in _hookexec
    return self._inner_hookexec(hook, methods, kwargs)
  File "c:\users\ssrk1\appdata\local\programs\python\python38-32\lib\site-packages\pluggy\manager.py", line 84, in &lt;lambda&gt;
    self._inner_hookexec = lambda hook, methods, kwargs: hook.multicall(
  File "c:\users\ssrk1\appdata\local\programs\python\python38-32\lib\site-packages\pluggy\callers.py", line 208, in _multicall
    return outcome.get_result()
  File "c:\users\ssrk1\appdata\local\programs\python\python38-32\lib\site-packages\pluggy\callers.py", line 80, in get_result
    raise ex[1].with_traceback(ex[2])
  File "c:\users\ssrk1\appdata\local\programs\python\python38-32\lib\site-packages\pluggy\callers.py", line 187, in _multicall
    res = hook_impl.function(*args)
  File "c:\users\ssrk1\appdata\local\programs\python\python38-32\lib\site-packages\_pytest\main.py", line 338, in pytest_runtestloop
    item.config.hook.pytest_runtest_protocol(item=item, nextitem=nextitem)
  File "c:\users\ssrk1\appdata\local\programs\python\python38-32\lib\site-packages\pluggy\hooks.py", line 286, in __call__
    return self._hookexec(self, self.get_hookimpls(), kwargs)
  File "c:\users\ssrk1\appdata\local\programs\python\python38-32\lib\site-packages\pluggy\manager.py", line 93, in _hookexec
    return self._inner_hookexec(hook, methods, kwargs)
  File "c:\users\ssrk1\appdata\local\programs\python\python38-32\lib\site-packages\pluggy\manager.py", line 84, in &lt;lambda&gt;
    self._inner_hookexec = lambda hook, methods, kwargs: hook.multicall(
  File "c:\users\ssrk1\appdata\local\programs\python\python38-32\lib\site-packages\pluggy\callers.py", line 208, in _multicall
    return outcome.get_result()
  File "c:\users\ssrk1\appdata\local\programs\python\python38-32\lib\site-packages\pluggy\callers.py", line 80, in get_result
    raise ex[1].with_traceback(ex[2])
  File "c:\users\ssrk1\appdata\local\programs\python\python38-32\lib\site-packages\pluggy\callers.py", line 187, in _multicall
    res = hook_impl.function(*args)
  File "c:\users\ssrk1\appdata\local\programs\python\python38-32\lib\site-packages\_pytest\runner.py", line 110, in pytest_runtest_protocol
    runtestprotocol(item, nextitem=nextitem)
  File "c:\users\ssrk1\appdata\local\programs\python\python38-32\lib\site-packages\_pytest\runner.py", line 127, in runtestprotocol
    reports.append(call_and_report(item, "call", log))
  File "c:\users\ssrk1\appdata\local\programs\python\python38-32\lib\site-packages\_pytest\runner.py", line 218, in call_and_report
    report = hook.pytest_runtest_makereport(item=item, call=call)  # type: TestReport
  File "c:\users\ssrk1\appdata\local\programs\python\python38-32\lib\site-packages\pluggy\hooks.py", line 286, in __call__
    return self._hookexec(self, self.get_hookimpls(), kwargs)
  File "c:\users\ssrk1\appdata\local\programs\python\python38-32\lib\site-packages\pluggy\manager.py", line 93, in _hookexec
    return self._inner_hookexec(hook, methods, kwargs)
  File "c:\users\ssrk1\appdata\local\programs\python\python38-32\lib\site-packages\pluggy\manager.py", line 84, in &lt;lambda&gt;
    self._inner_hookexec = lambda hook, methods, kwargs: hook.multicall(
  File "c:\users\ssrk1\appdata\local\programs\python\python38-32\lib\site-packages\pluggy\callers.py", line 203, in _multicall
    gen.send(outcome)
  File "C:\Users\ssrk1\Selenium\Project-001\tests\conftest.py", line 43, in pytest_runtest_makereport
    _capture_screenshot(file_name)
  File "C:\Users\ssrk1\Selenium\Project-001\tests\conftest.py", line 52, in _capture_screenshot
    driver.get_screenshot_as_file(name)
  File "c:\users\ssrk1\appdata\local\programs\python\python38-32\lib\site-packages\selenium\webdriver\remote\webdriver.py", line 1032, in get_screenshot_as_file
    png = self.get_screenshot_as_png()
  File "c:\users\ssrk1\appdata\local\programs\python\python38-32\lib\site-packages\selenium\webdriver\remote\webdriver.py", line 1064, in get_screenshot_as_png
    return base64.b64decode(self.get_screenshot_as_base64().encode('ascii'))
  File "c:\users\ssrk1\appdata\local\programs\python\python38-32\lib\site-packages\selenium\webdriver\remote\webdriver.py", line 1074, in get_screenshot_as_base64
    return self.execute(Command.SCREENSHOT)['value']
  File "c:\users\ssrk1\appdata\local\programs\python\python38-32\lib\site-packages\selenium\webdriver\remote\webdriver.py", line 321, in execute
    self.error_handler.check_response(response)
  File "c:\users\ssrk1\appdata\local\programs\python\python38-32\lib\site-packages\selenium\webdriver\remote\errorhandler.py", line 242, in check_response
    raise exception_class(message, screen, stacktrace)
selenium.common.exceptions.TimeoutException: Message: timeout: Timed out receiving message from renderer: 10.000
  (Session info: chrome=87.0.4280.141)</error></testcase></testsuite></testsuites>